Workbook

Sheet Chests_Dashboard
A1: =_xlfn.LET(_xlpm.d,TODAY(), _xlpm.monday,_xlpm.d-WEEKDAY(_xlpm.d,2)+1, TEXT(_xlpm.monday,"dd.mm.yyyy") & " - " & TEXT(_xlpm.monday+6,"dd.mm.yyyy")) -> 04.05.2026 - 10.05.2026 | C1: L5 Crypt | D1: L10 Crypt | E1: L15 Crypt | F1: L20 Crypt | G1: L25 Crypt | H1: L10 rare Crypt | I1: L15 rare Crypt | J1: L20 rare Crypt | K1: L25 rare Crypt | L1: L30 rare Crypt | M1: L15 epic Crypt | N1: L20 epic Crypt | O1: L25 epic Crypt | P1: L30 epic Crypt | Q1: L35 epic Crypt | R1: L10 Citadel | S1: L15 Citadel | T1: L20 Citadel | U1: L25 Citadel | V1: L30 Citadel | W1: L16-24 Heroic | X1: L25-30 Heroic | Y1: L31+ Heroic | Z1: L40+ Heroic | AA1: Bank | AB1: Ragnarok Chests | AC1: Olympus Chests | AD1: Ancients vaults | AE1: Others | AF1: L10 Tartaros Crypt | AG1: L15 Tartaros Crypt | AH1: L20 Tartaros Crypt | AI1: L25 Tartaros Crypt | AJ1: L30 Tartaros Crypt | AK1: L35 Tartaros Crypt | AL1: Ancients Chests | AM1: Epic Monster Chests
A2: Points per chest: | C2: 10 | D2: 20 | E2: 30 | F2: 40 | G2: 50 | H2: 10 | I2: 20 | J2: 20 | K2: 50 | L2: 80 | M2: 30 | N2: 50 | O2: 100 | P2: 200 | Q2: 300 | R2: 10 | S2: 20 | T2: 50 | U2: 160 | V2: 250 | W2: 20 | X2: 40 | Y2: 80 | Z2: 200 | AA2: 40 | AB2: 20 | AC2: 20 | AD2: 50 | AE2: 5 | AF2: 10 | AG2: 20 | AH2: 30 | AI2: 40 | AJ2: 80 | AK2: 120 | AL2: 0.1 | AM2: 100
A3: Weekly requirement -> | B3: 2000 | C3: Total Chest Count -> | H3: =SUM(C4:AM4) -> 1760
A4: Total Chest Point -> | B4: =SUM(B5:B120) -> 36710 | C4: =SUM(C5:C111) -> 293 | D4: =SUM(D5:D111) -> 585 | E4: =SUM(E5:E111) -> 304 | F4: =SUM(F5:F111) -> 30 | G4: =SUM(G5:G111) -> 0 | H4: =SUM(H5:H111) -> 127 | I4: =SUM(I5:I111) -> 10 | J4: =SUM(J5:J111) -> 3 | ... AM4: =SUM(AM5:AM111) -> 0
A5: =chests_counter!$H2 -> Absolutus | B5: {=IF(A5<>"", SUMPRODUCT(($C$2:$AM$2<>0)*(C5:AM5<>0)*($C$2:$AM$2)*(C5:AM5)), "")} -> 230 | C5: =IF($A5="","",IF(C$1="","",COUNTIFS(tbl_chests[from],$A5,tbl_chests[legalized],C$1,tbl_chests[datetime],">="&TODAY()-WEEKDAY(TODAY(),2)+1,tbl_chests[datetime],"<"&TODAY()-WEEKDAY(TODAY(),2)+8))) -> 5 | D5: =IF($A5="","",IF(D$1="","",COUNTIFS(tbl_chests[from],$A5,tbl_chests[legalized],D$1,tbl_chests[datetime],">="&TODAY()-WEEKDAY(TODAY(),2)+1,tbl_chests[datetime],"<"&TODAY()-WEEKDAY(TODAY(),2)+8))) -> 9 | E5: =IF($A5="","",IF(E$1="","",COUNTIFS(tbl_chests[from],$A5,tbl_chests[legalized],E$1,tbl_chests[datetime],">="&TODAY()-WEEKDAY(TODAY(),2)+1,tbl_chests[datetime],"<"&TODAY()-WEEKDAY(TODAY(),2)+8))) -> 0 | F5: =IF($A5="","",IF(F$1="","",COUNTIFS(tbl_chests[from],$A5,tbl_chests[legalized],F$1,tbl_chests[datetime],">="&TODAY()-WEEKDAY(TODAY(),2)+1,tbl_chests[datetime],"<"&TODAY()-WEEKDAY(TODAY(),2)+8))) -> 0 | G5: =IF($A5="","",IF(G$1="","",COUNTIFS(tbl_chests[from],$A5,tbl_chests[legalized],G$1,tbl_chests[datetime],">="&TODAY()-WEEKDAY(TODAY(),2)+1,tbl_chests[datetime],"<"&TODAY()-WEEKDAY(TODAY(),2)+8))) -> 0 | H5: =IF($A5="","",IF(H$1="","",COUNTIFS(tbl_chests[from],$A5,tbl_chests[legalized],H$1,tbl_chests[datetime],">="&TODAY()-WEEKDAY(TODAY(),2)+1,tbl_chests[datetime],"<"&TODAY()-WEEKDAY(TODAY(),2)+8))) -> 0 | I5: =IF($A5="","",IF(I$1="","",COUNTIFS(tbl_chests[from],$A5,tbl_chests[legalized],I$1,tbl_chests[datetime],">="&TODAY()-WEEKDAY(TODAY(),2)+1,tbl_chests[datetime],"<"&TODAY()-WEEKDAY(TODAY(),2)+8))) -> 0 | J5: =IF($A5="","",IF(J$1="","",COUNTIFS(tbl_chests[from],$A5,tbl_chests[legalized],J$1,tbl_chests[datetime],">="&TODAY()-WEEKDAY(TODAY(),2)+1,tbl_chests[datetime],"<"&TODAY()-WEEKDAY(TODAY(),2)+8))) -> 0 | ... AM5: =IF($A5="","",IF(AM$1="","",COUNTIFS(tbl_chests[from],$A5,tbl_chests[legalized],AM$1,tbl_chests[datetime],">="&TODAY()-WEEKDAY(TODAY(),2)+1,tbl_chests[datetime],"<"&TODAY()-WEEKDAY(TODAY(),2)+8))) -> 0
A6: =chests_counter!$H3 -> Agagas | B6: {=IF(A6<>"", SUMPRODUCT(($C$2:$AM$2<>0)*(C6:AM6<>0)*($C$2:$AM$2)*(C6:AM6)), "")} -> 140 | C6: =IF($A6="","",IF(C$1="","",COUNTIFS(tbl_chests[from],$A6,tbl_chests[legalized],C$1,tbl_chests[datetime],">="&TODAY()-WEEKDAY(TODAY(),2)+1,tbl_chests[datetime],"<"&TODAY()-WEEKDAY(TODAY(),2)+8))) -> 2 | D6: =IF($A6="","",IF(D$1="","",COUNTIFS(tbl_chests[from],$A6,tbl_chests[legalized],D$1,tbl_chests[datetime],">="&TODAY()-WEEKDAY(TODAY(),2)+1,tbl_chests[datetime],"<"&TODAY()-WEEKDAY(TODAY(),2)+8))) -> 6 | E6: =IF($A6="","",IF(E$1="","",COUNTIFS(tbl_chests[from],$A6,tbl_chests[legalized],E$1,tbl_chests[datetime],">="&TODAY()-WEEKDAY(TODAY(),2)+1,tbl_chests[datetime],"<"&TODAY()-WEEKDAY(TODAY(),2)+8))) -> 0 | F6: =IF($A6="","",IF(F$1="","",COUNTIFS(tbl_chests[from],$A6,tbl_chests[legalized],F$1,tbl_chests[datetime],">="&TODAY()-WEEKDAY(TODAY(),2)+1,tbl_chests[datetime],"<"&TODAY()-WEEKDAY(TODAY(),2)+8))) -> 0 | G6: =IF($A6="","",IF(G$1="","",COUNTIFS(tbl_chests[from],$A6,tbl_chests[legalized],G$1,tbl_chests[datetime],">="&TODAY()-WEEKDAY(TODAY(),2)+1,tbl_chests[datetime],"<"&TODAY()-WEEKDAY(TODAY(),2)+8))) -> 0 | H6: =IF($A6="","",IF(H$1="","",COUNTIFS(tbl_chests[from],$A6,tbl_chests[legalized],H$1,tbl_chests[datetime],">="&TODAY()-WEEKDAY(TODAY(),2)+1,tbl_chests[datetime],"<"&TODAY()-WEEKDAY(TODAY(),2)+8))) -> 0 | I6: =IF($A6="","",IF(I$1="","",COUNTIFS(tbl_chests[from],$A6,tbl_chests[legalized],I$1,tbl_chests[datetime],">="&TODAY()-WEEKDAY(TODAY(),2)+1,tbl_chests[datetime],"<"&TODAY()-WEEKDAY(TODAY(),2)+8))) -> 0 | J6: =IF($A6="","",IF(J$1="","",COUNTIFS(tbl_chests[from],$A6,tbl_chests[legalized],J$1,tbl_chests[datetime],">="&TODAY()-WEEKDAY(TODAY(),2)+1,tbl_chests[datetime],"<"&TODAY()-WEEKDAY(TODAY(),2)+8))) -> 0 | ... AM6: =IF($A6="","",IF(AM$1="","",COUNTIFS(tbl_chests[from],$A6,tbl_chests[legalized],AM$1,tbl_chests[datetime],">="&TODAY()-WEEKDAY(TODAY(),2)+1,tbl_chests[datetime],"<"&TODAY()-WEEKDAY(TODAY(),2)+8))) -> 0
A7: =chests_counter!$H4 -> AL CAPONE | B7: {=IF(A7<>"", SUMPRODUCT(($C$2:$AM$2<>0)*(C7:AM7<>0)*($C$2:$AM$2)*(C7:AM7)), "")} -> 180 | C7: =IF($A7="","",IF(C$1="","",COUNTIFS(tbl_chests[from],$A7,tbl_chests[legalized],C$1,tbl_chests[datetime],">="&TODAY()-WEEKDAY(TODAY(),2)+1,tbl_chests[datetime],"<"&TODAY()-WEEKDAY(TODAY(),2)+8))) -> 11 | D7: =IF($A7="","",IF(D$1="","",COUNTIFS(tbl_chests[from],$A7,tbl_chests[legalized],D$1,tbl_chests[datetime],">="&TODAY()-WEEKDAY(TODAY(),2)+1,tbl_chests[datetime],"<"&TODAY()-WEEKDAY(TODAY(),2)+8))) -> 2 | E7: =IF($A7="","",IF(E$1="","",COUNTIFS(tbl_chests[from],$A7,tbl_chests[legalized],E$1,tbl_chests[datetime],">="&TODAY()-WEEKDAY(TODAY(),2)+1,tbl_chests[datetime],"<"&TODAY()-WEEKDAY(TODAY(),2)+8))) -> 1 | F7: =IF($A7="","",IF(F$1="","",COUNTIFS(tbl_chests[from],$A7,tbl_chests[legalized],F$1,tbl_chests[datetime],">="&TODAY()-WEEKDAY(TODAY(),2)+1,tbl_chests[datetime],"<"&TODAY()-WEEKDAY(TODAY(),2)+8))) -> 0 | G7: =IF($A7="","",IF(G$1="","",COUNTIFS(tbl_chests[from],$A7,tbl_chests[legalized],G$1,tbl_chests[datetime],">="&TODAY()-WEEKDAY(TODAY(),2)+1,tbl_chests[datetime],"<"&TODAY()-WEEKDAY(TODAY(),2)+8))) -> 0 | H7: =IF($A7="","",IF(H$1="","",COUNTIFS(tbl_chests[from],$A7,tbl_chests[legalized],H$1,tbl_chests[datetime],">="&TODAY()-WEEKDAY(TODAY(),2)+1,tbl_chests[datetime],"<"&TODAY()-WEEKDAY(TODAY(),2)+8))) -> 0 | I7: =IF($A7="","",IF(I$1="","",COUNTIFS(tbl_chests[from],$A7,tbl_chests[legalized],I$1,tbl_chests[datetime],">="&TODAY()-WEEKDAY(TODAY(),2)+1,tbl_chests[datetime],"<"&TODAY()-WEEKDAY(TODAY(),2)+8))) -> 0 | J7: =IF($A7="","",IF(J$1="","",COUNTIFS(tbl_chests[from],$A7,tbl_chests[legalized],J$1,tbl_chests[datetime],">="&TODAY()-WEEKDAY(TODAY(),2)+1,tbl_chests[datetime],"<"&TODAY()-WEEKDAY(TODAY(),2)+8))) -> 0 | ... AM7: =IF($A7="","",IF(AM$1="","",COUNTIFS(tbl_chests[from],$A7,tbl_chests[legalized],AM$1,tbl_chests[datetime],">="&TODAY()-WEEKDAY(TODAY(),2)+1,tbl_chests[datetime],"<"&TODAY()-WEEKDAY(TODAY(),2)+8))) -> 0
A8: =chests_counter!$H5 -> aladred | B8: {=IF(A8<>"", SUMPRODUCT(($C$2:$AM$2<>0)*(C8:AM8<>0)*($C$2:$AM$2)*(C8:AM8)), "")} -> 160 | C8: =IF($A8="","",IF(C$1="","",COUNTIFS(tbl_chests[from],$A8,tbl_chests[legalized],C$1,tbl_chests[datetime],">="&TODAY()-WEEKDAY(TODAY(),2)+1,tbl_chests[datetime],"<"&TODAY()-WEEKDAY(TODAY(),2)+8))) -> 1 | D8: =IF($A8="","",IF(D$1="","",COUNTIFS(tbl_chests[from],$A8,tbl_chests[legalized],D$1,tbl_chests[datetime],">="&TODAY()-WEEKDAY(TODAY(),2)+1,tbl_chests[datetime],"<"&TODAY()-WEEKDAY(TODAY(),2)+8))) -> 1 | E8: =IF($A8="","",IF(E$1="","",COUNTIFS(tbl_chests[from],$A8,tbl_chests[legalized],E$1,tbl_chests[datetime],">="&TODAY()-WEEKDAY(TODAY(),2)+1,tbl_chests[datetime],"<"&TODAY()-WEEKDAY(TODAY(),2)+8))) -> 0 | F8: =IF($A8="","",IF(F$1="","",COUNTIFS(tbl_chests[from],$A8,tbl_chests[legalized],F$1,tbl_chests[datetime],">="&TODAY()-WEEKDAY(TODAY(),2)+1,tbl_chests[datetime],"<"&TODAY()-WEEKDAY(TODAY(),2)+8))) -> 0 | G8: =IF($A8="","",IF(G$1="","",COUNTIFS(tbl_chests[from],$A8,tbl_chests[legalized],G$1,tbl_chests[datetime],">="&TODAY()-WEEKDAY(TODAY(),2)+1,tbl_chests[datetime],"<"&TODAY()-WEEKDAY(TODAY(),2)+8))) -> 0 | H8: =IF($A8="","",IF(H$1="","",COUNTIFS(tbl_chests[from],$A8,tbl_chests[legalized],H$1,tbl_chests[datetime],">="&TODAY()-WEEKDAY(TODAY(),2)+1,tbl_chests[datetime],"<"&TODAY()-WEEKDAY(TODAY(),2)+8))) -> 0 | I8: =IF($A8="","",IF(I$1="","",COUNTIFS(tbl_chests[from],$A8,tbl_chests[legalized],I$1,tbl_chests[datetime],">="&TODAY()-WEEKDAY(TODAY(),2)+1,tbl_chests[datetime],"<"&TODAY()-WEEKDAY(TODAY(),2)+8))) -> 0 | J8: =IF($A8="","",IF(J$1="","",COUNTIFS(tbl_chests[from],$A8,tbl_chests[legalized],J$1,tbl_chests[datetime],">="&TODAY()-WEEKDAY(TODAY(),2)+1,tbl_chests[datetime],"<"&TODAY()-WEEKDAY(TODAY(),2)+8))) -> 0 | ... AM8: =IF($A8="","",IF(AM$1="","",COUNTIFS(tbl_chests[from],$A8,tbl_chests[legalized],AM$1,tbl_chests[datetime],">="&TODAY()-WEEKDAY(TODAY(),2)+1,tbl_chests[datetime],"<"&TODAY()-WEEKDAY(TODAY(),2)+8))) -> 0
A9: =chests_counter!$H6 -> Amr ibn al Aas | B9: {=IF(A9<>"", SUMPRODUCT(($C$2:$AM$2<>0)*(C9:AM9<>0)*($C$2:$AM$2)*(C9:AM9)), "")} -> 590 | C9: =IF($A9="","",IF(C$1="","",COUNTIFS(tbl_chests[from],$A9,tbl_chests[legalized],C$1,tbl_chests[datetime],">="&TODAY()-WEEKDAY(TODAY(),2)+1,tbl_chests[datetime],"<"&TODAY()-WEEKDAY(TODAY(),2)+8))) -> 2 | D9: =IF($A9="","",IF(D$1="","",COUNTIFS(tbl_chests[from],$A9,tbl_chests[legalized],D$1,tbl_chests[datetime],">="&TODAY()-WEEKDAY(TODAY(),2)+1,tbl_chests[datetime],"<"&TODAY()-WEEKDAY(TODAY(),2)+8))) -> 14 | E9: =IF($A9="","",IF(E$1="","",COUNTIFS(tbl_chests[from],$A9,tbl_chests[legalized],E$1,tbl_chests[datetime],">="&TODAY()-WEEKDAY(TODAY(),2)+1,tbl_chests[datetime],"<"&TODAY()-WEEKDAY(TODAY(),2)+8))) -> 6 | F9: =IF($A9="","",IF(F$1="","",COUNTIFS(tbl_chests[from],$A9,tbl_chests[legalized],F$1,tbl_chests[datetime],">="&TODAY()-WEEKDAY(TODAY(),2)+1,tbl_chests[datetime],"<"&TODAY()-WEEKDAY(TODAY(),2)+8))) -> 0 | G9: =IF($A9="","",IF(G$1="","",COUNTIFS(tbl_chests[from],$A9,tbl_chests[legalized],G$1,tbl_chests[datetime],">="&TODAY()-WEEKDAY(TODAY(),2)+1,tbl_chests[datetime],"<"&TODAY()-WEEKDAY(TODAY(),2)+8))) -> 0 | H9: =IF($A9="","",IF(H$1="","",COUNTIFS(tbl_chests[from],$A9,tbl_chests[legalized],H$1,tbl_chests[datetime],">="&TODAY()-WEEKDAY(TODAY(),2)+1,tbl_chests[datetime],"<"&TODAY()-WEEKDAY(TODAY(),2)+8))) -> 4 | I9: =IF($A9="","",IF(I$1="","",COUNTIFS(tbl_chests[from],$A9,tbl_chests[legalized],I$1,tbl_chests[datetime],">="&TODAY()-WEEKDAY(TODAY(),2)+1,tbl_chests[datetime],"<"&TODAY()-WEEKDAY(TODAY(),2)+8))) -> 0 | J9: =IF($A9="","",IF(J$1="","",COUNTIFS(tbl_chests[from],$A9,tbl_chests[legalized],J$1,tbl_chests[datetime],">="&TODAY()-WEEKDAY(TODAY(),2)+1,tbl_chests[datetime],"<"&TODAY()-WEEKDAY(TODAY(),2)+8))) -> 0 | ... AM9: =IF($A9="","",IF(AM$1="","",COUNTIFS(tbl_chests[from],$A9,tbl_chests[legalized],AM$1,tbl_chests[datetime],">="&TODAY()-WEEKDAY(TODAY(),2)+1,tbl_chests[datetime],"<"&TODAY()-WEEKDAY(TODAY(),2)+8))) -> 0
A10: =chests_counter!$H7 -> Angel | B10: {=IF(A10<>"", SUMPRODUCT(($C$2:$AM$2<>0)*(C10:AM10<>0)*($C$2:$AM$2)*(C10:AM10)), "")} -> 755 | C10: =IF($A10="","",IF(C$1="","",COUNTIFS(tbl_chests[from],$A10,tbl_chests[legalized],C$1,tbl_chests[datetime],">="&TODAY()-WEEKDAY(TODAY(),2)+1,tbl_chests[datetime],"<"&TODAY()-WEEKDAY(TODAY(),2)+8))) -> 0 | D10: =IF($A10="","",IF(D$1="","",COUNTIFS(tbl_chests[from],$A10,tbl_chests[legalized],D$1,tbl_chests[datetime],">="&TODAY()-WEEKDAY(TODAY(),2)+1,tbl_chests[datetime],"<"&TODAY()-WEEKDAY(TODAY(),2)+8))) -> 1 | E10: =IF($A10="","",IF(E$1="","",COUNTIFS(tbl_chests[from],$A10,tbl_chests[legalized],E$1,tbl_chests[datetime],">="&TODAY()-WEEKDAY(TODAY(),2)+1,tbl_chests[datetime],"<"&TODAY()-WEEKDAY(TODAY(),2)+8))) -> 7 | F10: =IF($A10="","",IF(F$1="","",COUNTIFS(tbl_chests[from],$A10,tbl_chests[legalized],F$1,tbl_chests[datetime],">="&TODAY()-WEEKDAY(TODAY(),2)+1,tbl_chests[datetime],"<"&TODAY()-WEEKDAY(TODAY(),2)+8))) -> 0 | G10: =IF($A10="","",IF(G$1="","",COUNTIFS(tbl_chests[from],$A10,tbl_chests[legalized],G$1,tbl_chests[datetime],">="&TODAY()-WEEKDAY(TODAY(),2)+1,tbl_chests[datetime],"<"&TODAY()-WEEKDAY(TODAY(),2)+8))) -> 0 | H10: =IF($A10="","",IF(H$1="","",COUNTIFS(tbl_chests[from],$A10,tbl_chests[legalized],H$1,tbl_chests[datetime],">="&TODAY()-WEEKDAY(TODAY(),2)+1,tbl_chests[datetime],"<"&TODAY()-WEEKDAY(TODAY(),2)+8))) -> 0 | I10: =IF($A10="","",IF(I$1="","",COUNTIFS(tbl_chests[from],$A10,tbl_chests[legalized],I$1,tbl_chests[datetime],">="&TODAY()-WEEKDAY(TODAY(),2)+1,tbl_chests[datetime],"<"&TODAY()-WEEKDAY(TODAY(),2)+8))) -> 0 | J10: =IF($A10="","",IF(J$1="","",COUNTIFS(tbl_chests[from],$A10,tbl_chests[legalized],J$1,tbl_chests[datetime],">="&TODAY()-WEEKDAY(TODAY(),2)+1,tbl_chests[datetime],"<"&TODAY()-WEEKDAY(TODAY(),2)+8))) -> 0 | ... AM10: =IF($A10="","",IF(AM$1="","",COUNTIFS(tbl_chests[from],$A10,tbl_chests[legalized],AM$1,tbl_chests[datetime],">="&TODAY()-WEEKDAY(TODAY(),2)+1,tbl_chests[datetime],"<"&TODAY()-WEEKDAY(TODAY(),2)+8))) -> 0
A11: =chests_counter!$H8 -> Arardin | B11: {=IF(A11<>"", SUMPRODUCT(($C$2:$AM$2<>0)*(C11:AM11<>0)*($C$2:$AM$2)*(C11:AM11)), "")} -> 35 | C11: =IF($A11="","",IF(C$1="","",COUNTIFS(tbl_chests[from],$A11,tbl_chests[legalized],C$1,tbl_chests[datetime],">="&TODAY()-WEEKDAY(TODAY(),2)+1,tbl_chests[datetime],"<"&TODAY()-WEEKDAY(TODAY(),2)+8))) -> 1 | D11: =IF($A11="","",IF(D$1="","",COUNTIFS(tbl_chests[from],$A11,tbl_chests[legalized],D$1,tbl_chests[datetime],">="&TODAY()-WEEKDAY(TODAY(),2)+1,tbl_chests[datetime],"<"&TODAY()-WEEKDAY(TODAY(),2)+8))) -> 1 | E11: =IF($A11="","",IF(E$1="","",COUNTIFS(tbl_chests[from],$A11,tbl_chests[legalized],E$1,tbl_chests[datetime],">="&TODAY()-WEEKDAY(TODAY(),2)+1,tbl_chests[datetime],"<"&TODAY()-WEEKDAY(TODAY(),2)+8))) -> 0 | F11: =IF($A11="","",IF(F$1="","",COUNTIFS(tbl_chests[from],$A11,tbl_chests[legalized],F$1,tbl_chests[datetime],">="&TODAY()-WEEKDAY(TODAY(),2)+1,tbl_chests[datetime],"<"&TODAY()-WEEKDAY(TODAY(),2)+8))) -> 0 | G11: =IF($A11="","",IF(G$1="","",COUNTIFS(tbl_chests[from],$A11,tbl_chests[legalized],G$1,tbl_chests[datetime],">="&TODAY()-WEEKDAY(TODAY(),2)+1,tbl_chests[datetime],"<"&TODAY()-WEEKDAY(TODAY(),2)+8))) -> 0 | H11: =IF($A11="","",IF(H$1="","",COUNTIFS(tbl_chests[from],$A11,tbl_chests[legalized],H$1,tbl_chests[datetime],">="&TODAY()-WEEKDAY(TODAY(),2)+1,tbl_chests[datetime],"<"&TODAY()-WEEKDAY(TODAY(),2)+8))) -> 0 | I11: =IF($A11="","",IF(I$1="","",COUNTIFS(tbl_chests[from],$A11,tbl_chests[legalized],I$1,tbl_chests[datetime],">="&TODAY()-WEEKDAY(TODAY(),2)+1,tbl_chests[datetime],"<"&TODAY()-WEEKDAY(TODAY(),2)+8))) -> 0 | J11: =IF($A11="","",IF(J$1="","",COUNTIFS(tbl_chests[from],$A11,tbl_chests[legalized],J$1,tbl_chests[datetime],">="&TODAY()-WEEKDAY(TODAY(),2)+1,tbl_chests[datetime],"<"&TODAY()-WEEKDAY(TODAY(),2)+8))) -> 0 | ... AM11: =IF($A11="","",IF(AM$1="","",COUNTIFS(tbl_chests[from],$A11,tbl_chests[legalized],AM$1,tbl_chests[datetime],">="&TODAY()-WEEKDAY(TODAY(),2)+1,tbl_chests[datetime],"<"&TODAY()-WEEKDAY(TODAY(),2)+8))) -> 0
A12: =chests_counter!$H9 -> ARBA33 | B12: {=IF(A12<>"", SUMPRODUCT(($C$2:$AM$2<>0)*(C12:AM12<>0)*($C$2:$AM$2)*(C12:AM12)), "")} -> 240 | C12: =IF($A12="","",IF(C$1="","",COUNTIFS(tbl_chests[from],$A12,tbl_chests[legalized],C$1,tbl_chests[datetime],">="&TODAY()-WEEKDAY(TODAY(),2)+1,tbl_chests[datetime],"<"&TODAY()-WEEKDAY(TODAY(),2)+8))) -> 9 | D12: =IF($A12="","",IF(D$1="","",COUNTIFS(tbl_chests[from],$A12,tbl_chests[legalized],D$1,tbl_chests[datetime],">="&TODAY()-WEEKDAY(TODAY(),2)+1,tbl_chests[datetime],"<"&TODAY()-WEEKDAY(TODAY(),2)+8))) -> 6 | E12: =IF($A12="","",IF(E$1="","",COUNTIFS(tbl_chests[from],$A12,tbl_chests[legalized],E$1,tbl_chests[datetime],">="&TODAY()-WEEKDAY(TODAY(),2)+1,tbl_chests[datetime],"<"&TODAY()-WEEKDAY(TODAY(),2)+8))) -> 1 | F12: =IF($A12="","",IF(F$1="","",COUNTIFS(tbl_chests[from],$A12,tbl_chests[legalized],F$1,tbl_chests[datetime],">="&TODAY()-WEEKDAY(TODAY(),2)+1,tbl_chests[datetime],"<"&TODAY()-WEEKDAY(TODAY(),2)+8))) -> 0 | G12: =IF($A12="","",IF(G$1="","",COUNTIFS(tbl_chests[from],$A12,tbl_chests[legalized],G$1,tbl_chests[datetime],">="&TODAY()-WEEKDAY(TODAY(),2)+1,tbl_chests[datetime],"<"&TODAY()-WEEKDAY(TODAY(),2)+8))) -> 0 | H12: =IF($A12="","",IF(H$1="","",COUNTIFS(tbl_chests[from],$A12,tbl_chests[legalized],H$1,tbl_chests[datetime],">="&TODAY()-WEEKDAY(TODAY(),2)+1,tbl_chests[datetime],"<"&TODAY()-WEEKDAY(TODAY(),2)+8))) -> 0 | I12: =IF($A12="","",IF(I$1="","",COUNTIFS(tbl_chests[from],$A12,tbl_chests[legalized],I$1,tbl_chests[datetime],">="&TODAY()-WEEKDAY(TODAY(),2)+1,tbl_chests[datetime],"<"&TODAY()-WEEKDAY(TODAY(),2)+8))) -> 0 | J12: =IF($A12="","",IF(J$1="","",COUNTIFS(tbl_chests[from],$A12,tbl_chests[legalized],J$1,tbl_chests[datetime],">="&TODAY()-WEEKDAY(TODAY(),2)+1,tbl_chests[datetime],"<"&TODAY()-WEEKDAY(TODAY(),2)+8))) -> 0 | ... AM12: =IF($A12="","",IF(AM$1="","",COUNTIFS(tbl_chests[from],$A12,tbl_chests[legalized],AM$1,tbl_chests[datetime],">="&TODAY()-WEEKDAY(TODAY(),2)+1,tbl_chests[datetime],"<"&TODAY()-WEEKDAY(TODAY(),2)+8))) -> 0
A13: =chests_counter!$H10 -> Attila the hun | B13: {=IF(A13<>"", SUMPRODUCT(($C$2:$AM$2<>0)*(C13:AM13<>0)*($C$2:$AM$2)*(C13:AM13)), "")} -> 495 | C13: =IF($A13="","",IF(C$1="","",COUNTIFS(tbl_chests[from],$A13,tbl_chests[legalized],C$1,tbl_chests[datetime],">="&TODAY()-WEEKDAY(TODAY(),2)+1,tbl_chests[datetime],"<"&TODAY()-WEEKDAY(TODAY(),2)+8))) -> 0 | D13: =IF($A13="","",IF(D$1="","",COUNTIFS(tbl_chests[from],$A13,tbl_chests[legalized],D$1,tbl_chests[datetime],">="&TODAY()-WEEKDAY(TODAY(),2)+1,tbl_chests[datetime],"<"&TODAY()-WEEKDAY(TODAY(),2)+8))) -> 1 | E13: =IF($A13="","",IF(E$1="","",COUNTIFS(tbl_chests[from],$A13,tbl_chests[legalized],E$1,tbl_chests[datetime],">="&TODAY()-WEEKDAY(TODAY(),2)+1,tbl_chests[datetime],"<"&TODAY()-WEEKDAY(TODAY(),2)+8))) -> 0 | F13: =IF($A13="","",IF(F$1="","",COUNTIFS(tbl_chests[from],$A13,tbl_chests[legalized],F$1,tbl_chests[datetime],">="&TODAY()-WEEKDAY(TODAY(),2)+1,tbl_chests[datetime],"<"&TODAY()-WEEKDAY(TODAY(),2)+8))) -> 0 | G13: =IF($A13="","",IF(G$1="","",COUNTIFS(tbl_chests[from],$A13,tbl_chests[legalized],G$1,tbl_chests[datetime],">="&TODAY()-WEEKDAY(TODAY(),2)+1,tbl_chests[datetime],"<"&TODAY()-WEEKDAY(TODAY(),2)+8))) -> 0 | H13: =IF($A13="","",IF(H$1="","",COUNTIFS(tbl_chests[from],$A13,tbl_chests[legalized],H$1,tbl_chests[datetime],">="&TODAY()-WEEKDAY(TODAY(),2)+1,tbl_chests[datetime],"<"&TODAY()-WEEKDAY(TODAY(),2)+8))) -> 0 | I13: =IF($A13="","",IF(I$1="","",COUNTIFS(tbl_chests[from],$A13,tbl_chests[legalized],I$1,tbl_chests[datetime],">="&TODAY()-WEEKDAY(TODAY(),2)+1,tbl_chests[datetime],"<"&TODAY()-WEEKDAY(TODAY(),2)+8))) -> 0 | J13: =IF($A13="","",IF(J$1="","",COUNTIFS(tbl_chests[from],$A13,tbl_chests[legalized],J$1,tbl_chests[datetime],">="&TODAY()-WEEKDAY(TODAY(),2)+1,tbl_chests[datetime],"<"&TODAY()-WEEKDAY(TODAY(),2)+8))) -> 0 | ... AM13: =IF($A13="","",IF(AM$1="","",COUNTIFS(tbl_chests[from],$A13,tbl_chests[legalized],AM$1,tbl_chests[datetime],">="&TODAY()-WEEKDAY(TODAY(),2)+1,tbl_chests[datetime],"<"&TODAY()-WEEKDAY(TODAY(),2)+8))) -> 0
A14: =chests_counter!$H11 -> Aurithris | B14: {=IF(A14<>"", SUMPRODUCT(($C$2:$AM$2<>0)*(C14:AM14<>0)*($C$2:$AM$2)*(C14:AM14)), "")} -> 0 | C14: =IF($A14="","",IF(C$1="","",COUNTIFS(tbl_chests[from],$A14,tbl_chests[legalized],C$1,tbl_chests[datetime],">="&TODAY()-WEEKDAY(TODAY(),2)+1,tbl_chests[datetime],"<"&TODAY()-WEEKDAY(TODAY(),2)+8))) -> 0 | D14: =IF($A14="","",IF(D$1="","",COUNTIFS(tbl_chests[from],$A14,tbl_chests[legalized],D$1,tbl_chests[datetime],">="&TODAY()-WEEKDAY(TODAY(),2)+1,tbl_chests[datetime],"<"&TODAY()-WEEKDAY(TODAY(),2)+8))) -> 0 | E14: =IF($A14="","",IF(E$1="","",COUNTIFS(tbl_chests[from],$A14,tbl_chests[legalized],E$1,tbl_chests[datetime],">="&TODAY()-WEEKDAY(TODAY(),2)+1,tbl_chests[datetime],"<"&TODAY()-WEEKDAY(TODAY(),2)+8))) -> 0 | F14: =IF($A14="","",IF(F$1="","",COUNTIFS(tbl_chests[from],$A14,tbl_chests[legalized],F$1,tbl_chests[datetime],">="&TODAY()-WEEKDAY(TODAY(),2)+1,tbl_chests[datetime],"<"&TODAY()-WEEKDAY(TODAY(),2)+8))) -> 0 | G14: =IF($A14="","",IF(G$1="","",COUNTIFS(tbl_chests[from],$A14,tbl_chests[legalized],G$1,tbl_chests[datetime],">="&TODAY()-WEEKDAY(TODAY(),2)+1,tbl_chests[datetime],"<"&TODAY()-WEEKDAY(TODAY(),2)+8))) -> 0 | H14: =IF($A14="","",IF(H$1="","",COUNTIFS(tbl_chests[from],$A14,tbl_chests[legalized],H$1,tbl_chests[datetime],">="&TODAY()-WEEKDAY(TODAY(),2)+1,tbl_chests[datetime],"<"&TODAY()-WEEKDAY(TODAY(),2)+8))) -> 0 | I14: =IF($A14="","",IF(I$1="","",COUNTIFS(tbl_chests[from],$A14,tbl_chests[legalized],I$1,tbl_chests[datetime],">="&TODAY()-WEEKDAY(TODAY(),2)+1,tbl_chests[datetime],"<"&TODAY()-WEEKDAY(TODAY(),2)+8))) -> 0 | J14: =IF($A14="","",IF(J$1="","",COUNTIFS(tbl_chests[from],$A14,tbl_chests[legalized],J$1,tbl_chests[datetime],">="&TODAY()-WEEKDAY(TODAY(),2)+1,tbl_chests[datetime],"<"&TODAY()-WEEKDAY(TODAY(),2)+8))) -> 0 | ... AM14: =IF($A14="","",IF(AM$1="","",COUNTIFS(tbl_chests[from],$A14,tbl_chests[legalized],AM$1,tbl_chests[datetime],">="&TODAY()-WEEKDAY(TODAY(),2)+1,tbl_chests[datetime],"<"&TODAY()-WEEKDAY(TODAY(),2)+8))) -> 0
A15: =chests_counter!$H12 -> bb steboulet 2 | B15: {=IF(A15<>"", SUMPRODUCT(($C$2:$AM$2<>0)*(C15:AM15<>0)*($C$2:$AM$2)*(C15:AM15)), "")} -> 0 | C15: =IF($A15="","",IF(C$1="","",COUNTIFS(tbl_chests[from],$A15,tbl_chests[legalized],C$1,tbl_chests[datetime],">="&TODAY()-WEEKDAY(TODAY(),2)+1,tbl_chests[datetime],"<"&TODAY()-WEEKDAY(TODAY(),2)+8))) -> 0 | D15: =IF($A15="","",IF(D$1="","",COUNTIFS(tbl_chests[from],$A15,tbl_chests[legalized],D$1,tbl_chests[datetime],">="&TODAY()-WEEKDAY(TODAY(),2)+1,tbl_chests[datetime],"<"&TODAY()-WEEKDAY(TODAY(),2)+8))) -> 0 | E15: =IF($A15="","",IF(E$1="","",COUNTIFS(tbl_chests[from],$A15,tbl_chests[legalized],E$1,tbl_chests[datetime],">="&TODAY()-WEEKDAY(TODAY(),2)+1,tbl_chests[datetime],"<"&TODAY()-WEEKDAY(TODAY(),2)+8))) -> 0 | F15: =IF($A15="","",IF(F$1="","",COUNTIFS(tbl_chests[from],$A15,tbl_chests[legalized],F$1,tbl_chests[datetime],">="&TODAY()-WEEKDAY(TODAY(),2)+1,tbl_chests[datetime],"<"&TODAY()-WEEKDAY(TODAY(),2)+8))) -> 0 | G15: =IF($A15="","",IF(G$1="","",COUNTIFS(tbl_chests[from],$A15,tbl_chests[legalized],G$1,tbl_chests[datetime],">="&TODAY()-WEEKDAY(TODAY(),2)+1,tbl_chests[datetime],"<"&TODAY()-WEEKDAY(TODAY(),2)+8))) -> 0 | H15: =IF($A15="","",IF(H$1="","",COUNTIFS(tbl_chests[from],$A15,tbl_chests[legalized],H$1,tbl_chests[datetime],">="&TODAY()-WEEKDAY(TODAY(),2)+1,tbl_chests[datetime],"<"&TODAY()-WEEKDAY(TODAY(),2)+8))) -> 0 | I15: =IF($A15="","",IF(I$1="","",COUNTIFS(tbl_chests[from],$A15,tbl_chests[legalized],I$1,tbl_chests[datetime],">="&TODAY()-WEEKDAY(TODAY(),2)+1,tbl_chests[datetime],"<"&TODAY()-WEEKDAY(TODAY(),2)+8))) -> 0 | J15: =IF($A15="","",IF(J$1="","",COUNTIFS(tbl_chests[from],$A15,tbl_chests[legalized],J$1,tbl_chests[datetime],">="&TODAY()-WEEKDAY(TODAY(),2)+1,tbl_chests[datetime],"<"&TODAY()-WEEKDAY(TODAY(),2)+8))) -> 0 | ... AM15: =IF($A15="","",IF(AM$1="","",COUNTIFS(tbl_chests[from],$A15,tbl_chests[legalized],AM$1,tbl_chests[datetime],">="&TODAY()-WEEKDAY(TODAY(),2)+1,tbl_chests[datetime],"<"&TODAY()-WEEKDAY(TODAY(),2)+8))) -> 0
A16: =chests_counter!$H13 -> Bella | B16: {=IF(A16<>"", SUMPRODUCT(($C$2:$AM$2<>0)*(C16:AM16<>0)*($C$2:$AM$2)*(C16:AM16)), "")} -> 0 | C16: =IF($A16="","",IF(C$1="","",COUNTIFS(tbl_chests[from],$A16,tbl_chests[legalized],C$1,tbl_chests[datetime],">="&TODAY()-WEEKDAY(TODAY(),2)+1,tbl_chests[datetime],"<"&TODAY()-WEEKDAY(TODAY(),2)+8))) -> 0 | D16: =IF($A16="","",IF(D$1="","",COUNTIFS(tbl_chests[from],$A16,tbl_chests[legalized],D$1,tbl_chests[datetime],">="&TODAY()-WEEKDAY(TODAY(),2)+1,tbl_chests[datetime],"<"&TODAY()-WEEKDAY(TODAY(),2)+8))) -> 0 | E16: =IF($A16="","",IF(E$1="","",COUNTIFS(tbl_chests[from],$A16,tbl_chests[legalized],E$1,tbl_chests[datetime],">="&TODAY()-WEEKDAY(TODAY(),2)+1,tbl_chests[datetime],"<"&TODAY()-WEEKDAY(TODAY(),2)+8))) -> 0 | F16: =IF($A16="","",IF(F$1="","",COUNTIFS(tbl_chests[from],$A16,tbl_chests[legalized],F$1,tbl_chests[datetime],">="&TODAY()-WEEKDAY(TODAY(),2)+1,tbl_chests[datetime],"<"&TODAY()-WEEKDAY(TODAY(),2)+8))) -> 0 | G16: =IF($A16="","",IF(G$1="","",COUNTIFS(tbl_chests[from],$A16,tbl_chests[legalized],G$1,tbl_chests[datetime],">="&TODAY()-WEEKDAY(TODAY(),2)+1,tbl_chests[datetime],"<"&TODAY()-WEEKDAY(TODAY(),2)+8))) -> 0 | H16: =IF($A16="","",IF(H$1="","",COUNTIFS(tbl_chests[from],$A16,tbl_chests[legalized],H$1,tbl_chests[datetime],">="&TODAY()-WEEKDAY(TODAY(),2)+1,tbl_chests[datetime],"<"&TODAY()-WEEKDAY(TODAY(),2)+8))) -> 0 | I16: =IF($A16="","",IF(I$1="","",COUNTIFS(tbl_chests[from],$A16,tbl_chests[legalized],I$1,tbl_chests[datetime],">="&TODAY()-WEEKDAY(TODAY(),2)+1,tbl_chests[datetime],"<"&TODAY()-WEEKDAY(TODAY(),2)+8))) -> 0 | J16: =IF($A16="","",IF(J$1="","",COUNTIFS(tbl_chests[from],$A16,tbl_chests[legalized],J$1,tbl_chests[datetime],">="&TODAY()-WEEKDAY(TODAY(),2)+1,tbl_chests[datetime],"<"&TODAY()-WEEKDAY(TODAY(),2)+8))) -> 0 | ... AM16: =IF($A16="","",IF(AM$1="","",COUNTIFS(tbl_chests[from],$A16,tbl_chests[legalized],AM$1,tbl_chests[datetime],">="&TODAY()-WEEKDAY(TODAY(),2)+1,tbl_chests[datetime],"<"&TODAY()-WEEKDAY(TODAY(),2)+8))) -> 0
... A35: =chests_counter!$H32 -> Gozahn | B35: {=IF(A35<>"", SUMPRODUCT(($C$2:$AM$2<>0)*(C35:AM35<>0)*($C$2:$AM$2)*(C35:AM35)), "")} -> 40 | C35: =IF($A35="","",IF(C$1="","",COUNTIFS(tbl_chests[from],$A35,tbl_chests[legalized],C$1,tbl_chests[datetime],">="&TODAY()-WEEKDAY(TODAY(),2)+1,tbl_chests[datetime],"<"&TODAY()-WEEKDAY(TODAY(),2)+8))) -> 2 | D35: =IF($A35="","",IF(D$1="","",COUNTIFS(tbl_chests[from],$A35,tbl_chests[legalized],D$1,tbl_chests[datetime],">="&TODAY()-WEEKDAY(TODAY(),2)+1,tbl_chests[datetime],"<"&TODAY()-WEEKDAY(TODAY(),2)+8))) -> 1 | E35: =IF($A35="","",IF(E$1="","",COUNTIFS(tbl_chests[from],$A35,tbl_chests[legalized],E$1,tbl_chests[datetime],">="&TODAY()-WEEKDAY(TODAY(),2)+1,tbl_chests[datetime],"<"&TODAY()-WEEKDAY(TODAY(),2)+8))) -> 0 | F35: =IF($A35="","",IF(F$1="","",COUNTIFS(tbl_chests[from],$A35,tbl_chests[legalized],F$1,tbl_chests[datetime],">="&TODAY()-WEEKDAY(TODAY(),2)+1,tbl_chests[datetime],"<"&TODAY()-WEEKDAY(TODAY(),2)+8))) -> 0 | G35: =IF($A35="","",IF(G$1="","",COUNTIFS(tbl_chests[from],$A35,tbl_chests[legalized],G$1,tbl_chests[datetime],">="&TODAY()-WEEKDAY(TODAY(),2)+1,tbl_chests[datetime],"<"&TODAY()-WEEKDAY(TODAY(),2)+8))) -> 0 | H35: =IF($A35="","",IF(H$1="","",COUNTIFS(tbl_chests[from],$A35,tbl_chests[legalized],H$1,tbl_chests[datetime],">="&TODAY()-WEEKDAY(TODAY(),2)+1,tbl_chests[datetime],"<"&TODAY()-WEEKDAY(TODAY(),2)+8))) -> 0 | I35: =IF($A35="","",IF(I$1="","",COUNTIFS(tbl_chests[from],$A35,tbl_chests[legalized],I$1,tbl_chests[datetime],">="&TODAY()-WEEKDAY(TODAY(),2)+1,tbl_chests[datetime],"<"&TODAY()-WEEKDAY(TODAY(),2)+8))) -> 0 | J35: =IF($A35="","",IF(J$1="","",COUNTIFS(tbl_chests[from],$A35,tbl_chests[legalized],J$1,tbl_chests[datetime],">="&TODAY()-WEEKDAY(TODAY(),2)+1,tbl_chests[datetime],"<"&TODAY()-WEEKDAY(TODAY(),2)+8))) -> 0 | ... AM35: =IF($A35="","",IF(AM$1="","",COUNTIFS(tbl_chests[from],$A35,tbl_chests[legalized],AM$1,tbl_chests[datetime],">="&TODAY()-WEEKDAY(TODAY(),2)+1,tbl_chests[datetime],"<"&TODAY()-WEEKDAY(TODAY(),2)+8))) -> 0
A36: =chests_counter!$H33 -> Iver | B36: {=IF(A36<>"", SUMPRODUCT(($C$2:$AM$2<>0)*(C36:AM36<>0)*($C$2:$AM$2)*(C36:AM36)), "")} -> 35 | C36: =IF($A36="","",IF(C$1="","",COUNTIFS(tbl_chests[from],$A36,tbl_chests[legalized],C$1,tbl_chests[datetime],">="&TODAY()-WEEKDAY(TODAY(),2)+1,tbl_chests[datetime],"<"&TODAY()-WEEKDAY(TODAY(),2)+8))) -> 0 | D36: =IF($A36="","",IF(D$1="","",COUNTIFS(tbl_chests[from],$A36,tbl_chests[legalized],D$1,tbl_chests[datetime],">="&TODAY()-WEEKDAY(TODAY(),2)+1,tbl_chests[datetime],"<"&TODAY()-WEEKDAY(TODAY(),2)+8))) -> 0 | E36: =IF($A36="","",IF(E$1="","",COUNTIFS(tbl_chests[from],$A36,tbl_chests[legalized],E$1,tbl_chests[datetime],">="&TODAY()-WEEKDAY(TODAY(),2)+1,tbl_chests[datetime],"<"&TODAY()-WEEKDAY(TODAY(),2)+8))) -> 1 | F36: =IF($A36="","",IF(F$1="","",COUNTIFS(tbl_chests[from],$A36,tbl_chests[legalized],F$1,tbl_chests[datetime],">="&TODAY()-WEEKDAY(TODAY(),2)+1,tbl_chests[datetime],"<"&TODAY()-WEEKDAY(TODAY(),2)+8))) -> 0 | G36: =IF($A36="","",IF(G$1="","",COUNTIFS(tbl_chests[from],$A36,tbl_chests[legalized],G$1,tbl_chests[datetime],">="&TODAY()-WEEKDAY(TODAY(),2)+1,tbl_chests[datetime],"<"&TODAY()-WEEKDAY(TODAY(),2)+8))) -> 0 | H36: =IF($A36="","",IF(H$1="","",COUNTIFS(tbl_chests[from],$A36,tbl_chests[legalized],H$1,tbl_chests[datetime],">="&TODAY()-WEEKDAY(TODAY(),2)+1,tbl_chests[datetime],"<"&TODAY()-WEEKDAY(TODAY(),2)+8))) -> 0 | I36: =IF($A36="","",IF(I$1="","",COUNTIFS(tbl_chests[from],$A36,tbl_chests[legalized],I$1,tbl_chests[datetime],">="&TODAY()-WEEKDAY(TODAY(),2)+1,tbl_chests[datetime],"<"&TODAY()-WEEKDAY(TODAY(),2)+8))) -> 0 | J36: =IF($A36="","",IF(J$1="","",COUNTIFS(tbl_chests[from],$A36,tbl_chests[legalized],J$1,tbl_chests[datetime],">="&TODAY()-WEEKDAY(TODAY(),2)+1,tbl_chests[datetime],"<"&TODAY()-WEEKDAY(TODAY(),2)+8))) -> 0 | ... AM36: =IF($A36="","",IF(AM$1="","",COUNTIFS(tbl_chests[from],$A36,tbl_chests[legalized],AM$1,tbl_chests[datetime],">="&TODAY()-WEEKDAY(TODAY(),2)+1,tbl_chests[datetime],"<"&TODAY()-WEEKDAY(TODAY(),2)+8))) -> 0 | BF36: =IF($A31 = "","",IF(BF$1 = "","",COUNTIFS(#REF!,$A31,#REF!,BF$1))) | BG36: =IF($A31 = "","",IF(BG$1 = "","",COUNTIFS(#REF!,$A31,#REF!,BG$1))) | BH36: =IF($A31 = "","",IF(BH$1 = "","",COUNTIFS(#REF!,$A31,#REF!,BH$1))) | BI36: =IF($A31 = "","",IF(BI$1 = "","",COUNTIFS(#REF!,$A31,#REF!,BI$1))) | BJ36: =IF($A31 = "","",IF(BJ$1 = "","",COUNTIFS(#REF!,$A31,#REF!,BJ$1))) | BK36: =IF($A31 = "","",IF(BK$1 = "","",COUNTIFS(#REF!,$A31,#REF!,BK$1))) | BL36: =IF($A31 = "","",IF(BL$1 = "","",COUNTIFS(#REF!,$A31,#REF!,BL$1))) | BM36: =IF($A31 = "","",IF(BM$1 = "","",COUNTIFS(#REF!,$A31,#REF!,BM$1))) | ... BO36: =IF($A31 = "","",IF(BO$1 = "","",COUNTIFS(#REF!,$A31,#REF!,BO$1)))
A37: =chests_counter!$H34 -> Jennifer | B37: {=IF(A37<>"", SUMPRODUCT(($C$2:$AM$2<>0)*(C37:AM37<>0)*($C$2:$AM$2)*(C37:AM37)), "")} -> 265 | C37: =IF($A37="","",IF(C$1="","",COUNTIFS(tbl_chests[from],$A37,tbl_chests[legalized],C$1,tbl_chests[datetime],">="&TODAY()-WEEKDAY(TODAY(),2)+1,tbl_chests[datetime],"<"&TODAY()-WEEKDAY(TODAY(),2)+8))) -> 0 | D37: =IF($A37="","",IF(D$1="","",COUNTIFS(tbl_chests[from],$A37,tbl_chests[legalized],D$1,tbl_chests[datetime],">="&TODAY()-WEEKDAY(TODAY(),2)+1,tbl_chests[datetime],"<"&TODAY()-WEEKDAY(TODAY(),2)+8))) -> 13 | E37: =IF($A37="","",IF(E$1="","",COUNTIFS(tbl_chests[from],$A37,tbl_chests[legalized],E$1,tbl_chests[datetime],">="&TODAY()-WEEKDAY(TODAY(),2)+1,tbl_chests[datetime],"<"&TODAY()-WEEKDAY(TODAY(),2)+8))) -> 0 | F37: =IF($A37="","",IF(F$1="","",COUNTIFS(tbl_chests[from],$A37,tbl_chests[legalized],F$1,tbl_chests[datetime],">="&TODAY()-WEEKDAY(TODAY(),2)+1,tbl_chests[datetime],"<"&TODAY()-WEEKDAY(TODAY(),2)+8))) -> 0 | G37: =IF($A37="","",IF(G$1="","",COUNTIFS(tbl_chests[from],$A37,tbl_chests[legalized],G$1,tbl_chests[datetime],">="&TODAY()-WEEKDAY(TODAY(),2)+1,tbl_chests[datetime],"<"&TODAY()-WEEKDAY(TODAY(),2)+8))) -> 0 | H37: =IF($A37="","",IF(H$1="","",COUNTIFS(tbl_chests[from],$A37,tbl_chests[legalized],H$1,tbl_chests[datetime],">="&TODAY()-WEEKDAY(TODAY(),2)+1,tbl_chests[datetime],"<"&TODAY()-WEEKDAY(TODAY(),2)+8))) -> 0 | I37: =IF($A37="","",IF(I$1="","",COUNTIFS(tbl_chests[from],$A37,tbl_chests[legalized],I$1,tbl_chests[datetime],">="&TODAY()-WEEKDAY(TODAY(),2)+1,tbl_chests[datetime],"<"&TODAY()-WEEKDAY(TODAY(),2)+8))) -> 0 | J37: =IF($A37="","",IF(J$1="","",COUNTIFS(tbl_chests[from],$A37,tbl_chests[legalized],J$1,tbl_chests[datetime],">="&TODAY()-WEEKDAY(TODAY(),2)+1,tbl_chests[datetime],"<"&TODAY()-WEEKDAY(TODAY(),2)+8))) -> 0 | ... AM37: =IF($A37="","",IF(AM$1="","",COUNTIFS(tbl_chests[from],$A37,tbl_chests[legalized],AM$1,tbl_chests[datetime],">="&TODAY()-WEEKDAY(TODAY(),2)+1,tbl_chests[datetime],"<"&TODAY()-WEEKDAY(TODAY(),2)+8))) -> 0
A38: =chests_counter!$H35 -> Kaachou | B38: {=IF(A38<>"", SUMPRODUCT(($C$2:$AM$2<>0)*(C38:AM38<>0)*($C$2:$AM$2)*(C38:AM38)), "")} -> 180 | C38: =IF($A38="","",IF(C$1="","",COUNTIFS(tbl_chests[from],$A38,tbl_chests[legalized],C$1,tbl_chests[datetime],">="&TODAY()-WEEKDAY(TODAY(),2)+1,tbl_chests[datetime],"<"&TODAY()-WEEKDAY(TODAY(),2)+8))) -> 0 | D38: =IF($A38="","",IF(D$1="","",COUNTIFS(tbl_chests[from],$A38,tbl_chests[legalized],D$1,tbl_chests[datetime],">="&TODAY()-WEEKDAY(TODAY(),2)+1,tbl_chests[datetime],"<"&TODAY()-WEEKDAY(TODAY(),2)+8))) -> 3 | E38: =IF($A38="","",IF(E$1="","",COUNTIFS(tbl_chests[from],$A38,tbl_chests[legalized],E$1,tbl_chests[datetime],">="&TODAY()-WEEKDAY(TODAY(),2)+1,tbl_chests[datetime],"<"&TODAY()-WEEKDAY(TODAY(),2)+8))) -> 0 | F38: =IF($A38="","",IF(F$1="","",COUNTIFS(tbl_chests[from],$A38,tbl_chests[legalized],F$1,tbl_chests[datetime],">="&TODAY()-WEEKDAY(TODAY(),2)+1,tbl_chests[datetime],"<"&TODAY()-WEEKDAY(TODAY(),2)+8))) -> 0 | G38: =IF($A38="","",IF(G$1="","",COUNTIFS(tbl_chests[from],$A38,tbl_chests[legalized],G$1,tbl_chests[datetime],">="&TODAY()-WEEKDAY(TODAY(),2)+1,tbl_chests[datetime],"<"&TODAY()-WEEKDAY(TODAY(),2)+8))) -> 0 | H38: =IF($A38="","",IF(H$1="","",COUNTIFS(tbl_chests[from],$A38,tbl_chests[legalized],H$1,tbl_chests[datetime],">="&TODAY()-WEEKDAY(TODAY(),2)+1,tbl_chests[datetime],"<"&TODAY()-WEEKDAY(TODAY(),2)+8))) -> 0 | I38: =IF($A38="","",IF(I$1="","",COUNTIFS(tbl_chests[from],$A38,tbl_chests[legalized],I$1,tbl_chests[datetime],">="&TODAY()-WEEKDAY(TODAY(),2)+1,tbl_chests[datetime],"<"&TODAY()-WEEKDAY(TODAY(),2)+8))) -> 0 | J38: =IF($A38="","",IF(J$1="","",COUNTIFS(tbl_chests[from],$A38,tbl_chests[legalized],J$1,tbl_chests[datetime],">="&TODAY()-WEEKDAY(TODAY(),2)+1,tbl_chests[datetime],"<"&TODAY()-WEEKDAY(TODAY(),2)+8))) -> 0 | ... AM38: =IF($A38="","",IF(AM$1="","",COUNTIFS(tbl_chests[from],$A38,tbl_chests[legalized],AM$1,tbl_chests[datetime],">="&TODAY()-WEEKDAY(TODAY(),2)+1,tbl_chests[datetime],"<"&TODAY()-WEEKDAY(TODAY(),2)+8))) -> 0
A39: =chests_counter!$H36 -> Kathrilis | B39: {=IF(A39<>"", SUMPRODUCT(($C$2:$AM$2<>0)*(C39:AM39<>0)*($C$2:$AM$2)*(C39:AM39)), "")} -> 0 | C39: =IF($A39="","",IF(C$1="","",COUNTIFS(tbl_chests[from],$A39,tbl_chests[legalized],C$1,tbl_chests[datetime],">="&TODAY()-WEEKDAY(TODAY(),2)+1,tbl_chests[datetime],"<"&TODAY()-WEEKDAY(TODAY(),2)+8))) -> 0 | D39: =IF($A39="","",IF(D$1="","",COUNTIFS(tbl_chests[from],$A39,tbl_chests[legalized],D$1,tbl_chests[datetime],">="&TODAY()-WEEKDAY(TODAY(),2)+1,tbl_chests[datetime],"<"&TODAY()-WEEKDAY(TODAY(),2)+8))) -> 0 | E39: =IF($A39="","",IF(E$1="","",COUNTIFS(tbl_chests[from],$A39,tbl_chests[legalized],E$1,tbl_chests[datetime],">="&TODAY()-WEEKDAY(TODAY(),2)+1,tbl_chests[datetime],"<"&TODAY()-WEEKDAY(TODAY(),2)+8))) -> 0 | F39: =IF($A39="","",IF(F$1="","",COUNTIFS(tbl_chests[from],$A39,tbl_chests[legalized],F$1,tbl_chests[datetime],">="&TODAY()-WEEKDAY(TODAY(),2)+1,tbl_chests[datetime],"<"&TODAY()-WEEKDAY(TODAY(),2)+8))) -> 0 | G39: =IF($A39="","",IF(G$1="","",COUNTIFS(tbl_chests[from],$A39,tbl_chests[legalized],G$1,tbl_chests[datetime],">="&TODAY()-WEEKDAY(TODAY(),2)+1,tbl_chests[datetime],"<"&TODAY()-WEEKDAY(TODAY(),2)+8))) -> 0 | H39: =IF($A39="","",IF(H$1="","",COUNTIFS(tbl_chests[from],$A39,tbl_chests[legalized],H$1,tbl_chests[datetime],">="&TODAY()-WEEKDAY(TODAY(),2)+1,tbl_chests[datetime],"<"&TODAY()-WEEKDAY(TODAY(),2)+8))) -> 0 | I39: =IF($A39="","",IF(I$1="","",COUNTIFS(tbl_chests[from],$A39,tbl_chests[legalized],I$1,tbl_chests[datetime],">="&TODAY()-WEEKDAY(TODAY(),2)+1,tbl_chests[datetime],"<"&TODAY()-WEEKDAY(TODAY(),2)+8))) -> 0 | J39: =IF($A39="","",IF(J$1="","",COUNTIFS(tbl_chests[from],$A39,tbl_chests[legalized],J$1,tbl_chests[datetime],">="&TODAY()-WEEKDAY(TODAY(),2)+1,tbl_chests[datetime],"<"&TODAY()-WEEKDAY(TODAY(),2)+8))) -> 0 | ... AM39: =IF($A39="","",IF(AM$1="","",COUNTIFS(tbl_chests[from],$A39,tbl_chests[legalized],AM$1,tbl_chests[datetime],">="&TODAY()-WEEKDAY(TODAY(),2)+1,tbl_chests[datetime],"<"&TODAY()-WEEKDAY(TODAY(),2)+8))) -> 0
A40: =chests_counter!$H37 -> Kibur | B40: {=IF(A40<>"", SUMPRODUCT(($C$2:$AM$2<>0)*(C40:AM40<>0)*($C$2:$AM$2)*(C40:AM40)), "")} -> 0 | C40: =IF($A40="","",IF(C$1="","",COUNTIFS(tbl_chests[from],$A40,tbl_chests[legalized],C$1,tbl_chests[datetime],">="&TODAY()-WEEKDAY(TODAY(),2)+1,tbl_chests[datetime],"<"&TODAY()-WEEKDAY(TODAY(),2)+8))) -> 0 | D40: =IF($A40="","",IF(D$1="","",COUNTIFS(tbl_chests[from],$A40,tbl_chests[legalized],D$1,tbl_chests[datetime],">="&TODAY()-WEEKDAY(TODAY(),2)+1,tbl_chests[datetime],"<"&TODAY()-WEEKDAY(TODAY(),2)+8))) -> 0 | E40: =IF($A40="","",IF(E$1="","",COUNTIFS(tbl_chests[from],$A40,tbl_chests[legalized],E$1,tbl_chests[datetime],">="&TODAY()-WEEKDAY(TODAY(),2)+1,tbl_chests[datetime],"<"&TODAY()-WEEKDAY(TODAY(),2)+8))) -> 0 | F40: =IF($A40="","",IF(F$1="","",COUNTIFS(tbl_chests[from],$A40,tbl_chests[legalized],F$1,tbl_chests[datetime],">="&TODAY()-WEEKDAY(TODAY(),2)+1,tbl_chests[datetime],"<"&TODAY()-WEEKDAY(TODAY(),2)+8))) -> 0 | G40: =IF($A40="","",IF(G$1="","",COUNTIFS(tbl_chests[from],$A40,tbl_chests[legalized],G$1,tbl_chests[datetime],">="&TODAY()-WEEKDAY(TODAY(),2)+1,tbl_chests[datetime],"<"&TODAY()-WEEKDAY(TODAY(),2)+8))) -> 0 | H40: =IF($A40="","",IF(H$1="","",COUNTIFS(tbl_chests[from],$A40,tbl_chests[legalized],H$1,tbl_chests[datetime],">="&TODAY()-WEEKDAY(TODAY(),2)+1,tbl_chests[datetime],"<"&TODAY()-WEEKDAY(TODAY(),2)+8))) -> 0 | I40: =IF($A40="","",IF(I$1="","",COUNTIFS(tbl_chests[from],$A40,tbl_chests[legalized],I$1,tbl_chests[datetime],">="&TODAY()-WEEKDAY(TODAY(),2)+1,tbl_chests[datetime],"<"&TODAY()-WEEKDAY(TODAY(),2)+8))) -> 0 | J40: =IF($A40="","",IF(J$1="","",COUNTIFS(tbl_chests[from],$A40,tbl_chests[legalized],J$1,tbl_chests[datetime],">="&TODAY()-WEEKDAY(TODAY(),2)+1,tbl_chests[datetime],"<"&TODAY()-WEEKDAY(TODAY(),2)+8))) -> 0 | ... AM40: =IF($A40="","",IF(AM$1="","",COUNTIFS(tbl_chests[from],$A40,tbl_chests[legalized],AM$1,tbl_chests[datetime],">="&TODAY()-WEEKDAY(TODAY(),2)+1,tbl_chests[datetime],"<"&TODAY()-WEEKDAY(TODAY(),2)+8))) -> 0
A41: =chests_counter!$H38 -> King Oliver | B41: {=IF(A41<>"", SUMPRODUCT(($C$2:$AM$2<>0)*(C41:AM41<>0)*($C$2:$AM$2)*(C41:AM41)), "")} -> 45 | C41: =IF($A41="","",IF(C$1="","",COUNTIFS(tbl_chests[from],$A41,tbl_chests[legalized],C$1,tbl_chests[datetime],">="&TODAY()-WEEKDAY(TODAY(),2)+1,tbl_chests[datetime],"<"&TODAY()-WEEKDAY(TODAY(),2)+8))) -> 1 | D41: =IF($A41="","",IF(D$1="","",COUNTIFS(tbl_chests[from],$A41,tbl_chests[legalized],D$1,tbl_chests[datetime],">="&TODAY()-WEEKDAY(TODAY(),2)+1,tbl_chests[datetime],"<"&TODAY()-WEEKDAY(TODAY(),2)+8))) -> 0 | E41: =IF($A41="","",IF(E$1="","",COUNTIFS(tbl_chests[from],$A41,tbl_chests[legalized],E$1,tbl_chests[datetime],">="&TODAY()-WEEKDAY(TODAY(),2)+1,tbl_chests[datetime],"<"&TODAY()-WEEKDAY(TODAY(),2)+8))) -> 1 | F41: =IF($A41="","",IF(F$1="","",COUNTIFS(tbl_chests[from],$A41,tbl_chests[legalized],F$1,tbl_chests[datetime],">="&TODAY()-WEEKDAY(TODAY(),2)+1,tbl_chests[datetime],"<"&TODAY()-WEEKDAY(TODAY(),2)+8))) -> 0 | G41: =IF($A41="","",IF(G$1="","",COUNTIFS(tbl_chests[from],$A41,tbl_chests[legalized],G$1,tbl_chests[datetime],">="&TODAY()-WEEKDAY(TODAY(),2)+1,tbl_chests[datetime],"<"&TODAY()-WEEKDAY(TODAY(),2)+8))) -> 0 | H41: =IF($A41="","",IF(H$1="","",COUNTIFS(tbl_chests[from],$A41,tbl_chests[legalized],H$1,tbl_chests[datetime],">="&TODAY()-WEEKDAY(TODAY(),2)+1,tbl_chests[datetime],"<"&TODAY()-WEEKDAY(TODAY(),2)+8))) -> 0 | I41: =IF($A41="","",IF(I$1="","",COUNTIFS(tbl_chests[from],$A41,tbl_chests[legalized],I$1,tbl_chests[datetime],">="&TODAY()-WEEKDAY(TODAY(),2)+1,tbl_chests[datetime],"<"&TODAY()-WEEKDAY(TODAY(),2)+8))) -> 0 | J41: =IF($A41="","",IF(J$1="","",COUNTIFS(tbl_chests[from],$A41,tbl_chests[legalized],J$1,tbl_chests[datetime],">="&TODAY()-WEEKDAY(TODAY(),2)+1,tbl_chests[datetime],"<"&TODAY()-WEEKDAY(TODAY(),2)+8))) -> 0 | ... AM41: =IF($A41="","",IF(AM$1="","",COUNTIFS(tbl_chests[from],$A41,tbl_chests[legalized],AM$1,tbl_chests[datetime],">="&TODAY()-WEEKDAY(TODAY(),2)+1,tbl_chests[datetime],"<"&TODAY()-WEEKDAY(TODAY(),2)+8))) -> 0
A42: =chests_counter!$H39 -> Lefinan | B42: {=IF(A42<>"", SUMPRODUCT(($C$2:$AM$2<>0)*(C42:AM42<>0)*($C$2:$AM$2)*(C42:AM42)), "")} -> 285 | C42: =IF($A42="","",IF(C$1="","",COUNTIFS(tbl_chests[from],$A42,tbl_chests[legalized],C$1,tbl_chests[datetime],">="&TODAY()-WEEKDAY(TODAY(),2)+1,tbl_chests[datetime],"<"&TODAY()-WEEKDAY(TODAY(),2)+8))) -> 1 | D42: =IF($A42="","",IF(D$1="","",COUNTIFS(tbl_chests[from],$A42,tbl_chests[legalized],D$1,tbl_chests[datetime],">="&TODAY()-WEEKDAY(TODAY(),2)+1,tbl_chests[datetime],"<"&TODAY()-WEEKDAY(TODAY(),2)+8))) -> 3 | E42: =IF($A42="","",IF(E$1="","",COUNTIFS(tbl_chests[from],$A42,tbl_chests[legalized],E$1,tbl_chests[datetime],">="&TODAY()-WEEKDAY(TODAY(),2)+1,tbl_chests[datetime],"<"&TODAY()-WEEKDAY(TODAY(),2)+8))) -> 3 | F42: =IF($A42="","",IF(F$1="","",COUNTIFS(tbl_chests[from],$A42,tbl_chests[legalized],F$1,tbl_chests[datetime],">="&TODAY()-WEEKDAY(TODAY(),2)+1,tbl_chests[datetime],"<"&TODAY()-WEEKDAY(TODAY(),2)+8))) -> 0 | G42: =IF($A42="","",IF(G$1="","",COUNTIFS(tbl_chests[from],$A42,tbl_chests[legalized],G$1,tbl_chests[datetime],">="&TODAY()-WEEKDAY(TODAY(),2)+1,tbl_chests[datetime],"<"&TODAY()-WEEKDAY(TODAY(),2)+8))) -> 0 | H42: =IF($A42="","",IF(H$1="","",COUNTIFS(tbl_chests[from],$A42,tbl_chests[legalized],H$1,tbl_chests[datetime],">="&TODAY()-WEEKDAY(TODAY(),2)+1,tbl_chests[datetime],"<"&TODAY()-WEEKDAY(TODAY(),2)+8))) -> 0 | I42: =IF($A42="","",IF(I$1="","",COUNTIFS(tbl_chests[from],$A42,tbl_chests[legalized],I$1,tbl_chests[datetime],">="&TODAY()-WEEKDAY(TODAY(),2)+1,tbl_chests[datetime],"<"&TODAY()-WEEKDAY(TODAY(),2)+8))) -> 0 | J42: =IF($A42="","",IF(J$1="","",COUNTIFS(tbl_chests[from],$A42,tbl_chests[legalized],J$1,tbl_chests[datetime],">="&TODAY()-WEEKDAY(TODAY(),2)+1,tbl_chests[datetime],"<"&TODAY()-WEEKDAY(TODAY(),2)+8))) -> 0 | ... AM42: =IF($A42="","",IF(AM$1="","",COUNTIFS(tbl_chests[from],$A42,tbl_chests[legalized],AM$1,tbl_chests[datetime],">="&TODAY()-WEEKDAY(TODAY(),2)+1,tbl_chests[datetime],"<"&TODAY()-WEEKDAY(TODAY(),2)+8))) -> 0 | BF42: =IF($A42 = "","",IF(BF$1 = "","",COUNTIFS(#REF!,$A42,#REF!,BF$1))) | BG42: =IF($A42 = "","",IF(BG$1 = "","",COUNTIFS(#REF!,$A42,#REF!,BG$1))) | BH42: =IF($A42 = "","",IF(BH$1 = "","",COUNTIFS(#REF!,$A42,#REF!,BH$1))) | BI42: =IF($A42 = "","",IF(BI$1 = "","",COUNTIFS(#REF!,$A42,#REF!,BI$1))) | BJ42: =IF($A42 = "","",IF(BJ$1 = "","",COUNTIFS(#REF!,$A42,#REF!,BJ$1))) | BK42: =IF($A42 = "","",IF(BK$1 = "","",COUNTIFS(#REF!,$A42,#REF!,BK$1))) | BL42: =IF($A42 = "","",IF(BL$1 = "","",COUNTIFS(#REF!,$A42,#REF!,BL$1))) | BM42: =IF($A42 = "","",IF(BM$1 = "","",COUNTIFS(#REF!,$A42,#REF!,BM$1))) | ... BO42: =IF($A42 = "","",IF(BO$1 = "","",COUNTIFS(#REF!,$A42,#REF!,BO$1)))
A43: =chests_counter!$H40 -> Lil Thog of Boomtown | B43: {=IF(A43<>"", SUMPRODUCT(($C$2:$AM$2<>0)*(C43:AM43<>0)*($C$2:$AM$2)*(C43:AM43)), "")} -> 2465 | C43: =IF($A43="","",IF(C$1="","",COUNTIFS(tbl_chests[from],$A43,tbl_chests[legalized],C$1,tbl_chests[datetime],">="&TODAY()-WEEKDAY(TODAY(),2)+1,tbl_chests[datetime],"<"&TODAY()-WEEKDAY(TODAY(),2)+8))) -> 0 | D43: =IF($A43="","",IF(D$1="","",COUNTIFS(tbl_chests[from],$A43,tbl_chests[legalized],D$1,tbl_chests[datetime],">="&TODAY()-WEEKDAY(TODAY(),2)+1,tbl_chests[datetime],"<"&TODAY()-WEEKDAY(TODAY(),2)+8))) -> 12 | E43: =IF($A43="","",IF(E$1="","",COUNTIFS(tbl_chests[from],$A43,tbl_chests[legalized],E$1,tbl_chests[datetime],">="&TODAY()-WEEKDAY(TODAY(),2)+1,tbl_chests[datetime],"<"&TODAY()-WEEKDAY(TODAY(),2)+8))) -> 44 | F43: =IF($A43="","",IF(F$1="","",COUNTIFS(tbl_chests[from],$A43,tbl_chests[legalized],F$1,tbl_chests[datetime],">="&TODAY()-WEEKDAY(TODAY(),2)+1,tbl_chests[datetime],"<"&TODAY()-WEEKDAY(TODAY(),2)+8))) -> 0 | G43: =IF($A43="","",IF(G$1="","",COUNTIFS(tbl_chests[from],$A43,tbl_chests[legalized],G$1,tbl_chests[datetime],">="&TODAY()-WEEKDAY(TODAY(),2)+1,tbl_chests[datetime],"<"&TODAY()-WEEKDAY(TODAY(),2)+8))) -> 0 | H43: =IF($A43="","",IF(H$1="","",COUNTIFS(tbl_chests[from],$A43,tbl_chests[legalized],H$1,tbl_chests[datetime],">="&TODAY()-WEEKDAY(TODAY(),2)+1,tbl_chests[datetime],"<"&TODAY()-WEEKDAY(TODAY(),2)+8))) -> 31 | I43: =IF($A43="","",IF(I$1="","",COUNTIFS(tbl_chests[from],$A43,tbl_chests[legalized],I$1,tbl_chests[datetime],">="&TODAY()-WEEKDAY(TODAY(),2)+1,tbl_chests[datetime],"<"&TODAY()-WEEKDAY(TODAY(),2)+8))) -> 0 | J43: =IF($A43="","",IF(J$1="","",COUNTIFS(tbl_chests[from],$A43,tbl_chests[legalized],J$1,tbl_chests[datetime],">="&TODAY()-WEEKDAY(TODAY(),2)+1,tbl_chests[datetime],"<"&TODAY()-WEEKDAY(TODAY(),2)+8))) -> 0 | ... AM43: =IF($A43="","",IF(AM$1="","",COUNTIFS(tbl_chests[from],$A43,tbl_chests[legalized],AM$1,tbl_chests[datetime],">="&TODAY()-WEEKDAY(TODAY(),2)+1,tbl_chests[datetime],"<"&TODAY()-WEEKDAY(TODAY(),2)+8))) -> 0
A44: =chests_counter!$H41 -> Lirosin | B44: {=IF(A44<>"", SUMPRODUCT(($C$2:$AM$2<>0)*(C44:AM44<>0)*($C$2:$AM$2)*(C44:AM44)), "")} -> 155 | C44: =IF($A44="","",IF(C$1="","",COUNTIFS(tbl_chests[from],$A44,tbl_chests[legalized],C$1,tbl_chests[datetime],">="&TODAY()-WEEKDAY(TODAY(),2)+1,tbl_chests[datetime],"<"&TODAY()-WEEKDAY(TODAY(),2)+8))) -> 3 | D44: =IF($A44="","",IF(D$1="","",COUNTIFS(tbl_chests[from],$A44,tbl_chests[legalized],D$1,tbl_chests[datetime],">="&TODAY()-WEEKDAY(TODAY(),2)+1,tbl_chests[datetime],"<"&TODAY()-WEEKDAY(TODAY(),2)+8))) -> 6 | E44: =IF($A44="","",IF(E$1="","",COUNTIFS(tbl_chests[from],$A44,tbl_chests[legalized],E$1,tbl_chests[datetime],">="&TODAY()-WEEKDAY(TODAY(),2)+1,tbl_chests[datetime],"<"&TODAY()-WEEKDAY(TODAY(),2)+8))) -> 0 | F44: =IF($A44="","",IF(F$1="","",COUNTIFS(tbl_chests[from],$A44,tbl_chests[legalized],F$1,tbl_chests[datetime],">="&TODAY()-WEEKDAY(TODAY(),2)+1,tbl_chests[datetime],"<"&TODAY()-WEEKDAY(TODAY(),2)+8))) -> 0 | G44: =IF($A44="","",IF(G$1="","",COUNTIFS(tbl_chests[from],$A44,tbl_chests[legalized],G$1,tbl_chests[datetime],">="&TODAY()-WEEKDAY(TODAY(),2)+1,tbl_chests[datetime],"<"&TODAY()-WEEKDAY(TODAY(),2)+8))) -> 0 | H44: =IF($A44="","",IF(H$1="","",COUNTIFS(tbl_chests[from],$A44,tbl_chests[legalized],H$1,tbl_chests[datetime],">="&TODAY()-WEEKDAY(TODAY(),2)+1,tbl_chests[datetime],"<"&TODAY()-WEEKDAY(TODAY(),2)+8))) -> 0 | I44: =IF($A44="","",IF(I$1="","",COUNTIFS(tbl_chests[from],$A44,tbl_chests[legalized],I$1,tbl_chests[datetime],">="&TODAY()-WEEKDAY(TODAY(),2)+1,tbl_chests[datetime],"<"&TODAY()-WEEKDAY(TODAY(),2)+8))) -> 0 | J44: =IF($A44="","",IF(J$1="","",COUNTIFS(tbl_chests[from],$A44,tbl_chests[legalized],J$1,tbl_chests[datetime],">="&TODAY()-WEEKDAY(TODAY(),2)+1,tbl_chests[datetime],"<"&TODAY()-WEEKDAY(TODAY(),2)+8))) -> 0 | ... AM44: =IF($A44="","",IF(AM$1="","",COUNTIFS(tbl_chests[from],$A44,tbl_chests[legalized],AM$1,tbl_chests[datetime],">="&TODAY()-WEEKDAY(TODAY(),2)+1,tbl_chests[datetime],"<"&TODAY()-WEEKDAY(TODAY(),2)+8))) -> 0
A45: =chests_counter!$H42 -> Luar | B45: {=IF(A45<>"", SUMPRODUCT(($C$2:$AM$2<>0)*(C45:AM45<>0)*($C$2:$AM$2)*(C45:AM45)), "")} -> 600 | C45: =IF($A45="","",IF(C$1="","",COUNTIFS(tbl_chests[from],$A45,tbl_chests[legalized],C$1,tbl_chests[datetime],">="&TODAY()-WEEKDAY(TODAY(),2)+1,tbl_chests[datetime],"<"&TODAY()-WEEKDAY(TODAY(),2)+8))) -> 3 | D45: =IF($A45="","",IF(D$1="","",COUNTIFS(tbl_chests[from],$A45,tbl_chests[legalized],D$1,tbl_chests[datetime],">="&TODAY()-WEEKDAY(TODAY(),2)+1,tbl_chests[datetime],"<"&TODAY()-WEEKDAY(TODAY(),2)+8))) -> 9 | E45: =IF($A45="","",IF(E$1="","",COUNTIFS(tbl_chests[from],$A45,tbl_chests[legalized],E$1,tbl_chests[datetime],">="&TODAY()-WEEKDAY(TODAY(),2)+1,tbl_chests[datetime],"<"&TODAY()-WEEKDAY(TODAY(),2)+8))) -> 3 | F45: =IF($A45="","",IF(F$1="","",COUNTIFS(tbl_chests[from],$A45,tbl_chests[legalized],F$1,tbl_chests[datetime],">="&TODAY()-WEEKDAY(TODAY(),2)+1,tbl_chests[datetime],"<"&TODAY()-WEEKDAY(TODAY(),2)+8))) -> 0 | G45: =IF($A45="","",IF(G$1="","",COUNTIFS(tbl_chests[from],$A45,tbl_chests[legalized],G$1,tbl_chests[datetime],">="&TODAY()-WEEKDAY(TODAY(),2)+1,tbl_chests[datetime],"<"&TODAY()-WEEKDAY(TODAY(),2)+8))) -> 0 | H45: =IF($A45="","",IF(H$1="","",COUNTIFS(tbl_chests[from],$A45,tbl_chests[legalized],H$1,tbl_chests[datetime],">="&TODAY()-WEEKDAY(TODAY(),2)+1,tbl_chests[datetime],"<"&TODAY()-WEEKDAY(TODAY(),2)+8))) -> 0 | I45: =IF($A45="","",IF(I$1="","",COUNTIFS(tbl_chests[from],$A45,tbl_chests[legalized],I$1,tbl_chests[datetime],">="&TODAY()-WEEKDAY(TODAY(),2)+1,tbl_chests[datetime],"<"&TODAY()-WEEKDAY(TODAY(),2)+8))) -> 1 | J45: =IF($A45="","",IF(J$1="","",COUNTIFS(tbl_chests[from],$A45,tbl_chests[legalized],J$1,tbl_chests[datetime],">="&TODAY()-WEEKDAY(TODAY(),2)+1,tbl_chests[datetime],"<"&TODAY()-WEEKDAY(TODAY(),2)+8))) -> 0 | ... AM45: =IF($A45="","",IF(AM$1="","",COUNTIFS(tbl_chests[from],$A45,tbl_chests[legalized],AM$1,tbl_chests[datetime],">="&TODAY()-WEEKDAY(TODAY(),2)+1,tbl_chests[datetime],"<"&TODAY()-WEEKDAY(TODAY(),2)+8))) -> 0
A46: =chests_counter!$H43 -> Luchfirilas | B46: {=IF(A46<>"", SUMPRODUCT(($C$2:$AM$2<>0)*(C46:AM46<>0)*($C$2:$AM$2)*(C46:AM46)), "")} -> 0 | C46: =IF($A46="","",IF(C$1="","",COUNTIFS(tbl_chests[from],$A46,tbl_chests[legalized],C$1,tbl_chests[datetime],">="&TODAY()-WEEKDAY(TODAY(),2)+1,tbl_chests[datetime],"<"&TODAY()-WEEKDAY(TODAY(),2)+8))) -> 0 | D46: =IF($A46="","",IF(D$1="","",COUNTIFS(tbl_chests[from],$A46,tbl_chests[legalized],D$1,tbl_chests[datetime],">="&TODAY()-WEEKDAY(TODAY(),2)+1,tbl_chests[datetime],"<"&TODAY()-WEEKDAY(TODAY(),2)+8))) -> 0 | E46: =IF($A46="","",IF(E$1="","",COUNTIFS(tbl_chests[from],$A46,tbl_chests[legalized],E$1,tbl_chests[datetime],">="&TODAY()-WEEKDAY(TODAY(),2)+1,tbl_chests[datetime],"<"&TODAY()-WEEKDAY(TODAY(),2)+8))) -> 0 | F46: =IF($A46="","",IF(F$1="","",COUNTIFS(tbl_chests[from],$A46,tbl_chests[legalized],F$1,tbl_chests[datetime],">="&TODAY()-WEEKDAY(TODAY(),2)+1,tbl_chests[datetime],"<"&TODAY()-WEEKDAY(TODAY(),2)+8))) -> 0 | G46: =IF($A46="","",IF(G$1="","",COUNTIFS(tbl_chests[from],$A46,tbl_chests[legalized],G$1,tbl_chests[datetime],">="&TODAY()-WEEKDAY(TODAY(),2)+1,tbl_chests[datetime],"<"&TODAY()-WEEKDAY(TODAY(),2)+8))) -> 0 | H46: =IF($A46="","",IF(H$1="","",COUNTIFS(tbl_chests[from],$A46,tbl_chests[legalized],H$1,tbl_chests[datetime],">="&TODAY()-WEEKDAY(TODAY(),2)+1,tbl_chests[datetime],"<"&TODAY()-WEEKDAY(TODAY(),2)+8))) -> 0 | I46: =IF($A46="","",IF(I$1="","",COUNTIFS(tbl_chests[from],$A46,tbl_chests[legalized],I$1,tbl_chests[datetime],">="&TODAY()-WEEKDAY(TODAY(),2)+1,tbl_chests[datetime],"<"&TODAY()-WEEKDAY(TODAY(),2)+8))) -> 0 | J46: =IF($A46="","",IF(J$1="","",COUNTIFS(tbl_chests[from],$A46,tbl_chests[legalized],J$1,tbl_chests[datetime],">="&TODAY()-WEEKDAY(TODAY(),2)+1,tbl_chests[datetime],"<"&TODAY()-WEEKDAY(TODAY(),2)+8))) -> 0 | ... AM46: =IF($A46="","",IF(AM$1="","",COUNTIFS(tbl_chests[from],$A46,tbl_chests[legalized],AM$1,tbl_chests[datetime],">="&TODAY()-WEEKDAY(TODAY(),2)+1,tbl_chests[datetime],"<"&TODAY()-WEEKDAY(TODAY(),2)+8))) -> 0
A47: =chests_counter!$H44 -> Maedrafir | B47: {=IF(A47<>"", SUMPRODUCT(($C$2:$AM$2<>0)*(C47:AM47<>0)*($C$2:$AM$2)*(C47:AM47)), "")} -> 125 | C47: =IF($A47="","",IF(C$1="","",COUNTIFS(tbl_chests[from],$A47,tbl_chests[legalized],C$1,tbl_chests[datetime],">="&TODAY()-WEEKDAY(TODAY(),2)+1,tbl_chests[datetime],"<"&TODAY()-WEEKDAY(TODAY(),2)+8))) -> 0 | D47: =IF($A47="","",IF(D$1="","",COUNTIFS(tbl_chests[from],$A47,tbl_chests[legalized],D$1,tbl_chests[datetime],">="&TODAY()-WEEKDAY(TODAY(),2)+1,tbl_chests[datetime],"<"&TODAY()-WEEKDAY(TODAY(),2)+8))) -> 0 | E47: =IF($A47="","",IF(E$1="","",COUNTIFS(tbl_chests[from],$A47,tbl_chests[legalized],E$1,tbl_chests[datetime],">="&TODAY()-WEEKDAY(TODAY(),2)+1,tbl_chests[datetime],"<"&TODAY()-WEEKDAY(TODAY(),2)+8))) -> 1 | F47: =IF($A47="","",IF(F$1="","",COUNTIFS(tbl_chests[from],$A47,tbl_chests[legalized],F$1,tbl_chests[datetime],">="&TODAY()-WEEKDAY(TODAY(),2)+1,tbl_chests[datetime],"<"&TODAY()-WEEKDAY(TODAY(),2)+8))) -> 1 | G47: =IF($A47="","",IF(G$1="","",COUNTIFS(tbl_chests[from],$A47,tbl_chests[legalized],G$1,tbl_chests[datetime],">="&TODAY()-WEEKDAY(TODAY(),2)+1,tbl_chests[datetime],"<"&TODAY()-WEEKDAY(TODAY(),2)+8))) -> 0 | H47: =IF($A47="","",IF(H$1="","",COUNTIFS(tbl_chests[from],$A47,tbl_chests[legalized],H$1,tbl_chests[datetime],">="&TODAY()-WEEKDAY(TODAY(),2)+1,tbl_chests[datetime],"<"&TODAY()-WEEKDAY(TODAY(),2)+8))) -> 0 | I47: =IF($A47="","",IF(I$1="","",COUNTIFS(tbl_chests[from],$A47,tbl_chests[legalized],I$1,tbl_chests[datetime],">="&TODAY()-WEEKDAY(TODAY(),2)+1,tbl_chests[datetime],"<"&TODAY()-WEEKDAY(TODAY(),2)+8))) -> 0 | J47: =IF($A47="","",IF(J$1="","",COUNTIFS(tbl_chests[from],$A47,tbl_chests[legalized],J$1,tbl_chests[datetime],">="&TODAY()-WEEKDAY(TODAY(),2)+1,tbl_chests[datetime],"<"&TODAY()-WEEKDAY(TODAY(),2)+8))) -> 0 | ... AM47: =IF($A47="","",IF(AM$1="","",COUNTIFS(tbl_chests[from],$A47,tbl_chests[legalized],AM$1,tbl_chests[datetime],">="&TODAY()-WEEKDAY(TODAY(),2)+1,tbl_chests[datetime],"<"&TODAY()-WEEKDAY(TODAY(),2)+8))) -> 0
A48: =chests_counter!$H45 -> Mario | B48: {=IF(A48<>"", SUMPRODUCT(($C$2:$AM$2<>0)*(C48:AM48<>0)*($C$2:$AM$2)*(C48:AM48)), "")} -> 40 | C48: =IF($A48="","",IF(C$1="","",COUNTIFS(tbl_chests[from],$A48,tbl_chests[legalized],C$1,tbl_chests[datetime],">="&TODAY()-WEEKDAY(TODAY(),2)+1,tbl_chests[datetime],"<"&TODAY()-WEEKDAY(TODAY(),2)+8))) -> 0 | D48: =IF($A48="","",IF(D$1="","",COUNTIFS(tbl_chests[from],$A48,tbl_chests[legalized],D$1,tbl_chests[datetime],">="&TODAY()-WEEKDAY(TODAY(),2)+1,tbl_chests[datetime],"<"&TODAY()-WEEKDAY(TODAY(),2)+8))) -> 2 | E48: =IF($A48="","",IF(E$1="","",COUNTIFS(tbl_chests[from],$A48,tbl_chests[legalized],E$1,tbl_chests[datetime],">="&TODAY()-WEEKDAY(TODAY(),2)+1,tbl_chests[datetime],"<"&TODAY()-WEEKDAY(TODAY(),2)+8))) -> 0 | F48: =IF($A48="","",IF(F$1="","",COUNTIFS(tbl_chests[from],$A48,tbl_chests[legalized],F$1,tbl_chests[datetime],">="&TODAY()-WEEKDAY(TODAY(),2)+1,tbl_chests[datetime],"<"&TODAY()-WEEKDAY(TODAY(),2)+8))) -> 0 | G48: =IF($A48="","",IF(G$1="","",COUNTIFS(tbl_chests[from],$A48,tbl_chests[legalized],G$1,tbl_chests[datetime],">="&TODAY()-WEEKDAY(TODAY(),2)+1,tbl_chests[datetime],"<"&TODAY()-WEEKDAY(TODAY(),2)+8))) -> 0 | H48: =IF($A48="","",IF(H$1="","",COUNTIFS(tbl_chests[from],$A48,tbl_chests[legalized],H$1,tbl_chests[datetime],">="&TODAY()-WEEKDAY(TODAY(),2)+1,tbl_chests[datetime],"<"&TODAY()-WEEKDAY(TODAY(),2)+8))) -> 0 | I48: =IF($A48="","",IF(I$1="","",COUNTIFS(tbl_chests[from],$A48,tbl_chests[legalized],I$1,tbl_chests[datetime],">="&TODAY()-WEEKDAY(TODAY(),2)+1,tbl_chests[datetime],"<"&TODAY()-WEEKDAY(TODAY(),2)+8))) -> 0 | J48: =IF($A48="","",IF(J$1="","",COUNTIFS(tbl_chests[from],$A48,tbl_chests[legalized],J$1,tbl_chests[datetime],">="&TODAY()-WEEKDAY(TODAY(),2)+1,tbl_chests[datetime],"<"&TODAY()-WEEKDAY(TODAY(),2)+8))) -> 0 | ... AM48: =IF($A48="","",IF(AM$1="","",COUNTIFS(tbl_chests[from],$A48,tbl_chests[legalized],AM$1,tbl_chests[datetime],">="&TODAY()-WEEKDAY(TODAY(),2)+1,tbl_chests[datetime],"<"&TODAY()-WEEKDAY(TODAY(),2)+8))) -> 0 | BF48: =IF($A48 = "","",IF(BF$1 = "","",COUNTIFS(#REF!,$A48,#REF!,BF$1))) | BG48: =IF($A48 = "","",IF(BG$1 = "","",COUNTIFS(#REF!,$A48,#REF!,BG$1))) | BH48: =IF($A48 = "","",IF(BH$1 = "","",COUNTIFS(#REF!,$A48,#REF!,BH$1))) | BI48: =IF($A48 = "","",IF(BI$1 = "","",COUNTIFS(#REF!,$A48,#REF!,BI$1))) | BJ48: =IF($A48 = "","",IF(BJ$1 = "","",COUNTIFS(#REF!,$A48,#REF!,BJ$1))) | BK48: =IF($A48 = "","",IF(BK$1 = "","",COUNTIFS(#REF!,$A48,#REF!,BK$1))) | BL48: =IF($A48 = "","",IF(BL$1 = "","",COUNTIFS(#REF!,$A48,#REF!,BL$1))) | BM48: =IF($A48 = "","",IF(BM$1 = "","",COUNTIFS(#REF!,$A48,#REF!,BM$1))) | ... BO48: =IF($A48 = "","",IF(BO$1 = "","",COUNTIFS(#REF!,$A48,#REF!,BO$1)))
A49: =chests_counter!$H46 -> Megrinad | B49: {=IF(A49<>"", SUMPRODUCT(($C$2:$AM$2<>0)*(C49:AM49<>0)*($C$2:$AM$2)*(C49:AM49)), "")} -> 125 | C49: =IF($A49="","",IF(C$1="","",COUNTIFS(tbl_chests[from],$A49,tbl_chests[legalized],C$1,tbl_chests[datetime],">="&TODAY()-WEEKDAY(TODAY(),2)+1,tbl_chests[datetime],"<"&TODAY()-WEEKDAY(TODAY(),2)+8))) -> 12 | D49: =IF($A49="","",IF(D$1="","",COUNTIFS(tbl_chests[from],$A49,tbl_chests[legalized],D$1,tbl_chests[datetime],">="&TODAY()-WEEKDAY(TODAY(),2)+1,tbl_chests[datetime],"<"&TODAY()-WEEKDAY(TODAY(),2)+8))) -> 0 | E49: =IF($A49="","",IF(E$1="","",COUNTIFS(tbl_chests[from],$A49,tbl_chests[legalized],E$1,tbl_chests[datetime],">="&TODAY()-WEEKDAY(TODAY(),2)+1,tbl_chests[datetime],"<"&TODAY()-WEEKDAY(TODAY(),2)+8))) -> 0 | F49: =IF($A49="","",IF(F$1="","",COUNTIFS(tbl_chests[from],$A49,tbl_chests[legalized],F$1,tbl_chests[datetime],">="&TODAY()-WEEKDAY(TODAY(),2)+1,tbl_chests[datetime],"<"&TODAY()-WEEKDAY(TODAY(),2)+8))) -> 0 | G49: =IF($A49="","",IF(G$1="","",COUNTIFS(tbl_chests[from],$A49,tbl_chests[legalized],G$1,tbl_chests[datetime],">="&TODAY()-WEEKDAY(TODAY(),2)+1,tbl_chests[datetime],"<"&TODAY()-WEEKDAY(TODAY(),2)+8))) -> 0 | H49: =IF($A49="","",IF(H$1="","",COUNTIFS(tbl_chests[from],$A49,tbl_chests[legalized],H$1,tbl_chests[datetime],">="&TODAY()-WEEKDAY(TODAY(),2)+1,tbl_chests[datetime],"<"&TODAY()-WEEKDAY(TODAY(),2)+8))) -> 0 | I49: =IF($A49="","",IF(I$1="","",COUNTIFS(tbl_chests[from],$A49,tbl_chests[legalized],I$1,tbl_chests[datetime],">="&TODAY()-WEEKDAY(TODAY(),2)+1,tbl_chests[datetime],"<"&TODAY()-WEEKDAY(TODAY(),2)+8))) -> 0 | J49: =IF($A49="","",IF(J$1="","",COUNTIFS(tbl_chests[from],$A49,tbl_chests[legalized],J$1,tbl_chests[datetime],">="&TODAY()-WEEKDAY(TODAY(),2)+1,tbl_chests[datetime],"<"&TODAY()-WEEKDAY(TODAY(),2)+8))) -> 0 | ... AM49: =IF($A49="","",IF(AM$1="","",COUNTIFS(tbl_chests[from],$A49,tbl_chests[legalized],AM$1,tbl_chests[datetime],">="&TODAY()-WEEKDAY(TODAY(),2)+1,tbl_chests[datetime],"<"&TODAY()-WEEKDAY(TODAY(),2)+8))) -> 0
